{
  "id": "lookout_atelier_riverside_v1",
  "width": 11,
  "depth": 9,
  "height": 8,
  "steps": [
    {
      "kind": "fill",
      "from": { "x": 0, "y": 0, "z": 0 },
      "to": { "x": 10, "y": 0, "z": 8 },
      "blockId": "minecraft:stone_bricks"
    },
    {
      "kind": "fill",
      "from": { "x": 0, "y": 1, "z": 0 },
      "to": { "x": 10, "y": 1, "z": 2 },
      "blockId": "minecraft:spruce_planks"
    },
    {
      "kind": "fill",
      "from": { "x": 1, "y": 1, "z": 3 },
      "to": { "x": 9, "y": 1, "z": 7 },
      "blockId": "minecraft:oak_planks"
    },
    {
      "kind": "fill",
      "from": { "x": 7, "y": 1, "z": 6 },
      "to": { "x": 10, "y": 1, "z": 8 },
      "blockId": "minecraft:dark_oak_planks"
    },
    {
      "kind": "fill",
      "from": { "x": 0, "y": 1, "z": 1 },
      "to": { "x": 0, "y": 4, "z": 1 },
      "blockId": "minecraft:stripped_oak_log"
    },
    {
      "kind": "fill",
      "from": { "x": 10, "y": 1, "z": 1 },
      "to": { "x": 10, "y": 4, "z": 1 },
      "blockId": "minecraft:stripped_oak_log"
    },
    {
      "kind": "fill",
      "from": { "x": 0, "y": 1, "z": 7 },
      "to": { "x": 0, "y": 4, "z": 7 },
      "blockId": "minecraft:stripped_oak_log"
    },
    {
      "kind": "fill",
      "from": { "x": 10, "y": 1, "z": 7 },
      "to": { "x": 10, "y": 4, "z": 7 },
      "blockId": "minecraft:stripped_oak_log"
    },
    {
      "kind": "fill",
      "from": { "x": 8, "y": 1, "z": 8 },
      "to": { "x": 10, "y": 5, "z": 8 },
      "blockId": "minecraft:cobblestone"
    },
    {
      "kind": "fill",
      "from": { "x": 1, "y": 2, "z": 3 },
      "to": { "x": 9, "y": 4, "z": 7 },
      "blockId": "minecraft:oak_planks"
    },
    {
      "kind": "fill",
      "from": { "x": 2, "y": 2, "z": 4 },
      "to": { "x": 8, "y": 4, "z": 6 },
      "blockId": "minecraft:air"
    },
    {
      "kind": "fill",
      "from": { "x": 2, "y": 2, "z": 3 },
      "to": { "x": 8, "y": 2, "z": 3 },
      "blockId": "minecraft:glass_pane"
    },
    {
      "kind": "fill",
      "from": { "x": 2, "y": 3, "z": 3 },
      "to": { "x": 8, "y": 3, "z": 3 },
      "blockId": "minecraft:glass_pane"
    },
    {
      "kind": "fill",
      "from": { "x": 1, "y": 2, "z": 4 },
      "to": { "x": 1, "y": 3, "z": 6 },
      "blockId": "minecraft:glass_pane"
    },
    {
      "kind": "fill",
      "from": { "x": 9, "y": 2, "z": 4 },
      "to": { "x": 9, "y": 3, "z": 6 },
      "blockId": "minecraft:glass_pane"
    },
    {
      "kind": "fill",
      "from": { "x": 4, "y": 2, "z": 7 },
      "to": { "x": 7, "y": 3, "z": 7 },
      "blockId": "minecraft:glass_pane"
    },
    {
      "kind": "fill",
      "from": { "x": 6, "y": 2, "z": 6 },
      "to": { "x": 10, "y": 5, "z": 8 },
      "blockId": "minecraft:cobblestone"
    },
    {
      "kind": "fill",
      "from": { "x": 7, "y": 3, "z": 7 },
      "to": { "x": 9, "y": 4, "z": 8 },
      "blockId": "minecraft:air"
    },
    {
      "kind": "fill",
      "from": { "x": 0, "y": 5, "z": 1 },
      "to": { "x": 5, "y": 5, "z": 3 },
      "blockId": "minecraft:dark_oak_planks"
    },
    {
      "kind": "fill",
      "from": { "x": 2, "y": 5, "z": 2 },
      "to": { "x": 10, "y": 5, "z": 8 },
      "blockId": "minecraft:dark_oak_planks"
    },
    {
      "kind": "fill",
      "from": { "x": 3, "y": 6, "z": 3 },
      "to": { "x": 10, "y": 6, "z": 8 },
      "blockId": "minecraft:dark_oak_planks"
    },
    {
      "kind": "fill",
      "from": { "x": 6, "y": 7, "z": 5 },
      "to": { "x": 10, "y": 7, "z": 8 },
      "blockId": "minecraft:dark_oak_slab"
    },
    {
      "kind": "fill",
      "from": { "x": 0, "y": 4, "z": 0 },
      "to": { "x": 10, "y": 4, "z": 0 },
      "blockId": "minecraft:spruce_slab"
    },
    {
      "kind": "fill",
      "from": { "x": 0, "y": 2, "z": 0 },
      "to": { "x": 10, "y": 2, "z": 0 },
      "blockId": "minecraft:spruce_fence"
    },
    {
      "kind": "block",
      "at": { "x": 5, "y": 2, "z": 3 },
      "blockId": "minecraft:chest"
    },
    {
      "kind": "block",
      "at": { "x": 7, "y": 2, "z": 5 },
      "blockId": "minecraft:crafting_table"
    },
    {
      "kind": "block",
      "at": { "x": 8, "y": 2, "z": 6 },
      "blockId": "minecraft:furnace"
    },
    {
      "kind": "block",
      "at": { "x": 7, "y": 3, "z": 6 },
      "blockId": "minecraft:bookshelf"
    },
    {
      "kind": "command",
      "commandTemplate": "setblock {x} {y} {z} minecraft:spruce_door[facing=south,half=lower,hinge=left,open=false]",
      "offset": { "x": 5, "y": 2, "z": 3 }
    },
    {
      "kind": "command",
      "commandTemplate": "setblock {x} {y} {z} minecraft:spruce_door[facing=south,half=upper,hinge=left,open=false]",
      "offset": { "x": 5, "y": 3, "z": 3 }
    },
    {
      "kind": "command",
      "commandTemplate": "setblock {x} {y} {z} minecraft:red_bed[facing=east,part=foot,occupied=false]",
      "offset": { "x": 2, "y": 2, "z": 6 }
    },
    {
      "kind": "command",
      "commandTemplate": "setblock {x} {y} {z} minecraft:red_bed[facing=east,part=head,occupied=false]",
      "offset": { "x": 3, "y": 2, "z": 6 }
    },
    {
      "kind": "command",
      "commandTemplate": "setblock {x} {y} {z} minecraft:lantern[hanging=true]",
      "offset": { "x": 3, "y": 4, "z": 4 }
    },
    {
      "kind": "command",
      "commandTemplate": "setblock {x} {y} {z} minecraft:lantern[hanging=true]",
      "offset": { "x": 7, "y": 4, "z": 4 }
    },
    {
      "kind": "command",
      "commandTemplate": "setblock {x} {y} {z} minecraft:lantern[hanging=true]",
      "offset": { "x": 8, "y": 5, "z": 7 }
    },
    {
      "kind": "command",
      "commandTemplate": "setblock {x} {y} {z} minecraft:dark_oak_stairs[facing=south,half=bottom,shape=straight]",
      "offset": { "x": 0, "y": 5, "z": 1 }
    },
    {
      "kind": "command",
      "commandTemplate": "setblock {x} {y} {z} minecraft:dark_oak_stairs[facing=south,half=bottom,shape=straight]",
      "offset": { "x": 10, "y": 5, "z": 1 }
    },
    {
      "kind": "command",
      "commandTemplate": "setblock {x} {y} {z} minecraft:dark_oak_stairs[facing=north,half=bottom,shape=straight]",
      "offset": { "x": 3, "y": 6, "z": 8 }
    },
    {
      "kind": "command",
      "commandTemplate": "setblock {x} {y} {z} minecraft:dark_oak_stairs[facing=north,half=bottom,shape=straight]",
      "offset": { "x": 8, "y": 6, "z": 8 }
    }
  ]
}
