{
  "id": "cantilever_cliff_house_v2",
  "width": 17,
  "depth": 17,
  "height": 17,
  "steps": [
    {
      "kind": "fill",
      "from": { "x": 8, "y": 5, "z": 6 },
      "to": { "x": 13, "y": 7, "z": 11 },
      "blockId": "minecraft:deepslate_bricks"
    },
    {
      "kind": "fill",
      "from": { "x": 9, "y": 4, "z": 7 },
      "to": { "x": 12, "y": 4, "z": 10 },
      "blockId": "minecraft:deepslate_bricks"
    },
    {
      "kind": "fill",
      "from": { "x": 4, "y": 4, "z": 7 },
      "to": { "x": 4, "y": 7, "z": 7 },
      "blockId": "minecraft:deepslate_brick_wall"
    },
    {
      "kind": "fill",
      "from": { "x": 4, "y": 4, "z": 10 },
      "to": { "x": 4, "y": 7, "z": 10 },
      "blockId": "minecraft:deepslate_brick_wall"
    },
    {
      "kind": "fill",
      "from": { "x": 6, "y": 7, "z": 8 },
      "to": { "x": 8, "y": 7, "z": 9 },
      "blockId": "minecraft:deepslate_tiles"
    },
    {
      "kind": "fill",
      "from": { "x": 8, "y": 8, "z": 6 },
      "to": { "x": 13, "y": 8, "z": 11 },
      "blockId": "minecraft:spruce_planks"
    },
    {
      "kind": "fill",
      "from": { "x": 3, "y": 8, "z": 7 },
      "to": { "x": 7, "y": 8, "z": 10 },
      "blockId": "minecraft:dark_oak_planks"
    },
    {
      "kind": "fill",
      "from": { "x": 8, "y": 9, "z": 6 },
      "to": { "x": 13, "y": 11, "z": 6 },
      "blockId": "minecraft:spruce_planks"
    },
    {
      "kind": "fill",
      "from": { "x": 8, "y": 9, "z": 11 },
      "to": { "x": 13, "y": 11, "z": 11 },
      "blockId": "minecraft:spruce_planks"
    },
    {
      "kind": "fill",
      "from": { "x": 8, "y": 9, "z": 7 },
      "to": { "x": 8, "y": 11, "z": 10 },
      "blockId": "minecraft:spruce_planks"
    },
    {
      "kind": "fill",
      "from": { "x": 13, "y": 9, "z": 7 },
      "to": { "x": 13, "y": 11, "z": 10 },
      "blockId": "minecraft:spruce_planks"
    },
    {
      "kind": "fill",
      "from": { "x": 8, "y": 9, "z": 6 },
      "to": { "x": 8, "y": 11, "z": 6 },
      "blockId": "minecraft:stripped_spruce_log"
    },
    {
      "kind": "fill",
      "from": { "x": 8, "y": 9, "z": 11 },
      "to": { "x": 8, "y": 11, "z": 11 },
      "blockId": "minecraft:stripped_spruce_log"
    },
    {
      "kind": "fill",
      "from": { "x": 13, "y": 9, "z": 6 },
      "to": { "x": 13, "y": 11, "z": 6 },
      "blockId": "minecraft:stripped_spruce_log"
    },
    {
      "kind": "fill",
      "from": { "x": 13, "y": 9, "z": 11 },
      "to": { "x": 13, "y": 11, "z": 11 },
      "blockId": "minecraft:stripped_spruce_log"
    },
    {
      "kind": "fill",
      "from": { "x": 8, "y": 9, "z": 8 },
      "to": { "x": 8, "y": 11, "z": 9 },
      "blockId": "minecraft:air"
    },
    {
      "kind": "fill",
      "from": { "x": 3, "y": 9, "z": 7 },
      "to": { "x": 3, "y": 11, "z": 10 },
      "blockId": "minecraft:glass"
    },
    {
      "kind": "fill",
      "from": { "x": 4, "y": 9, "z": 7 },
      "to": { "x": 7, "y": 11, "z": 7 },
      "blockId": "minecraft:glass"
    },
    {
      "kind": "fill",
      "from": { "x": 4, "y": 9, "z": 10 },
      "to": { "x": 7, "y": 11, "z": 10 },
      "blockId": "minecraft:glass"
    },
    {
      "kind": "fill",
      "from": { "x": 10, "y": 9, "z": 11 },
      "to": { "x": 12, "y": 10, "z": 11 },
      "blockId": "minecraft:glass_pane"
    },
    {
      "kind": "fill",
      "from": { "x": 8, "y": 12, "z": 7 },
      "to": { "x": 8, "y": 12, "z": 10 },
      "blockId": "minecraft:spruce_planks"
    },
    {
      "kind": "fill",
      "from": { "x": 8, "y": 13, "z": 8 },
      "to": { "x": 8, "y": 13, "z": 9 },
      "blockId": "minecraft:spruce_planks"
    },
    {
      "kind": "fill",
      "from": { "x": 13, "y": 12, "z": 7 },
      "to": { "x": 13, "y": 12, "z": 10 },
      "blockId": "minecraft:spruce_planks"
    },
    {
      "kind": "fill",
      "from": { "x": 13, "y": 13, "z": 8 },
      "to": { "x": 13, "y": 13, "z": 9 },
      "blockId": "minecraft:spruce_planks"
    },
    {
      "kind": "fill",
      "from": { "x": 3, "y": 12, "z": 7 },
      "to": { "x": 8, "y": 12, "z": 10 },
      "blockId": "minecraft:dark_oak_slab"
    },
    {
      "kind": "fill",
      "from": { "x": 6, "y": 12, "z": 5 },
      "to": { "x": 14, "y": 12, "z": 5 },
      "blockId": "minecraft:spruce_slab"
    },
    {
      "kind": "fill",
      "from": { "x": 6, "y": 12, "z": 6 },
      "to": { "x": 14, "y": 12, "z": 6 },
      "blockId": "minecraft:spruce_planks"
    },
    {
      "kind": "fill",
      "from": { "x": 6, "y": 12, "z": 11 },
      "to": { "x": 14, "y": 12, "z": 11 },
      "blockId": "minecraft:spruce_planks"
    },
    {
      "kind": "fill",
      "from": { "x": 6, "y": 12, "z": 12 },
      "to": { "x": 14, "y": 12, "z": 12 },
      "blockId": "minecraft:spruce_slab"
    },
    {
      "kind": "fill",
      "from": { "x": 6, "y": 13, "z": 7 },
      "to": { "x": 14, "y": 13, "z": 7 },
      "blockId": "minecraft:spruce_slab"
    },
    {
      "kind": "fill",
      "from": { "x": 6, "y": 13, "z": 8 },
      "to": { "x": 14, "y": 13, "z": 8 },
      "blockId": "minecraft:spruce_planks"
    },
    {
      "kind": "fill",
      "from": { "x": 6, "y": 13, "z": 9 },
      "to": { "x": 14, "y": 13, "z": 9 },
      "blockId": "minecraft:spruce_planks"
    },
    {
      "kind": "fill",
      "from": { "x": 6, "y": 13, "z": 10 },
      "to": { "x": 14, "y": 13, "z": 10 },
      "blockId": "minecraft:spruce_slab"
    },
    {
      "kind": "fill",
      "from": { "x": 7, "y": 14, "z": 8 },
      "to": { "x": 14, "y": 14, "z": 9 },
      "blockId": "minecraft:spruce_slab"
    },
    {
      "kind": "block",
      "at": { "x": 13, "y": 10, "z": 8 },
      "blockId": "minecraft:glass_pane"
    },
    {
      "kind": "block",
      "at": { "x": 13, "y": 10, "z": 9 },
      "blockId": "minecraft:glass_pane"
    },
    {
      "kind": "block",
      "at": { "x": 11, "y": 10, "z": 6 },
      "blockId": "minecraft:glass_pane"
    },
    {
      "kind": "block",
      "at": { "x": 11, "y": 10, "z": 11 },
      "blockId": "minecraft:glass_pane"
    },
    {
      "kind": "command",
      "commandTemplate": "setblock {x} {y} {z} minecraft:spruce_door[facing=north,half=lower,hinge=left]",
      "offset": { "x": 9, "y": 9, "z": 6 }
    },
    {
      "kind": "command",
      "commandTemplate": "setblock {x} {y} {z} minecraft:spruce_door[facing=north,half=upper,hinge=left]",
      "offset": { "x": 9, "y": 10, "z": 6 }
    },
    {
      "kind": "command",
      "commandTemplate": "setblock {x} {y} {z} minecraft:spruce_stairs[facing=south]",
      "offset": { "x": 9, "y": 8, "z": 5 }
    },
    {
      "kind": "command",
      "commandTemplate": "setblock {x} {y} {z} minecraft:red_bed[facing=east,part=foot]",
      "offset": { "x": 11, "y": 9, "z": 8 }
    },
    {
      "kind": "command",
      "commandTemplate": "setblock {x} {y} {z} minecraft:red_bed[facing=east,part=head]",
      "offset": { "x": 12, "y": 9, "z": 8 }
    },
    {
      "kind": "block",
      "at": { "x": 12, "y": 9, "z": 10 },
      "blockId": "minecraft:crafting_table"
    },
    {
      "kind": "command",
      "commandTemplate": "setblock {x} {y} {z} minecraft:barrel[facing=up]",
      "offset": { "x": 12, "y": 9, "z": 9 }
    },
    {
      "kind": "command",
      "commandTemplate": "setblock {x} {y} {z} minecraft:furnace[facing=west]",
      "offset": { "x": 12, "y": 9, "z": 7 }
    },
    {
      "kind": "block",
      "at": { "x": 5, "y": 9, "z": 8 },
      "blockId": "minecraft:bookshelf"
    },
    {
      "kind": "command",
      "commandTemplate": "setblock {x} {y} {z} minecraft:dark_oak_stairs[facing=east]",
      "offset": { "x": 5, "y": 9, "z": 9 }
    },
    {
      "kind": "command",
      "commandTemplate": "setblock {x} {y} {z} minecraft:lantern[hanging=true]",
      "offset": { "x": 10, "y": 12, "z": 8 }
    },
    {
      "kind": "command",
      "commandTemplate": "setblock {x} {y} {z} minecraft:lantern[hanging=false]",
      "offset": { "x": 5, "y": 10, "z": 8 }
    }
  ]
}
